Workbook

Sheet Start Here
A1: CONSTRUCTION CALCULATOR - INDIA
A2: Plan, estimate and track your build or renovation. Yellow cells are for you to fill in. Green cells calculate automatically.
A3: EXAMPLE RENOVATION: sample kitchen, bathroom and bedroom work with placeholder rates. Use the blank master file for your own project.
A4: START IN 5 STEPS
A5: Step | B5: Where | C5: What to do
A6: 1 | B6: Quick Start | C6: Answer the six questions: project name, client, built-up area, budget, city, and Feet or Metres.
A7: 2 | B7: Rates | C7: Type in your local rates. Costs stay at zero until you do.
A8: 3 | B8: Room Area to Steel | C8: Enter room sizes, openings and quantities in the yellow boxes.
A9: 4 | B9: Cost Estimate | C9: Add costs for items the calculators don't cover. Tag each one with a stage.
A10: 5 | B10: Order List and Stage Budget | C10: Use the Order List to buy materials, and the Stage Budget to check money stage by stage.
A12: WHAT'S INSIDE
A13: Tab | B13: What it does
A14: Quick Start | B14: Six answers to start: name, client, area, budget, city, and Feet or Metres.
A15: Assumptions | B15: Every factor the calculations use, with where to change it and its source status.
A16: Terms & Disclaimer | B16: What this file is, what it is not, and what remains to be completed before sale.
A17: Setup | B17: Project type, contingency and GST. Name, area, budget and units come from Quick Start.
A18: Room Area | B18: Floor area of each room, in sq ft and sq m.
A19: Earthwork | B19: Volume of soil to dig for foundations, trenches and pits, with cost.
A20: Paint & Tiles | B20: Paint litres and tile count, totalled for every room.
A21: Exterior & Roof | B21: Outside wall paint and flat roof waterproofing, with labour.
A22: Room Costs | B22: Paint and tile cost for each room, with each room's share.
A23: Concrete | B23: Concrete volume, cement, sand and aggregate quantities, and cost.
A24: Bricks & Blocks | B24: Brick count, AAC block count and masonry labour.
... A43: Rate Library | B43: Keep supplier rates by city and copy them to Rates.
A45: IMPORTANT
A46: - These are estimates for planning. They are not a structural design. Have a qualified engineer check the design and quantities.
A47: - Rates, wastage and coverage vary by supplier and site. Replace the blank rates with your own quotes before relying on the totals.
A48: - Sheets are protected with no password. To change a formula: Review > Unprotect Sheet.
A49: - Costs appear only after you enter rates on the Rates tab. Until then, every cost shows zero.
A50: - Changing Units does not convert numbers you have already typed. Re-enter them after switching.
A51: - This file does NOT calculate: plumbing and electrical quantities, the price of doors and windows, external wall painting, waterproofing area, roofing, labour for tiles and paint, transport, approval fees, backfilling and soil removal. Enter these by hand or get quotes.
A52: - Paint is calculated on walls only. Ceilings are not painted in the calculation. Add ceiling paint under Other.
A53: - The estimate uses the brick option only. AAC blocks are calculated on the Bricks & Blocks tab but are not in the Cost Estimate. Choose one or the other.
A54: - Tested in LibreOffice only. Not yet tested in Microsoft Excel or Google Sheets.
A55: - The Assumptions tab lists every factor the calculations use. The Terms tab sets out what the file is and is not. Read both before relying on any figure.

Sheet Quick Start
A1: QUICK START
A2: Answer these six questions first. The rest of the file uses your answers.
A3: EXAMPLE RENOVATION: placeholder rates and quantities. These totals are NOT a real estimate.
A4: Question | B4: Your answer | C4: Why we need it
A5: Project name | B5: My Home Project | C5: Shown on every tab and on the quotation
A6: Client / owner | C6: Shown on the quotation
A7: Built-up area | B7: 1500 | C7: Total floor area of the building, in the units you choose below
A8: Target budget (₹) | B8: 2500000 | C8: The most you plan to spend
A9: City | B9: Chennai | C9: For your reference
A10: Units | B10: Feet | C10: Feet or Metres. Set this before you measure anything. Changing it does not convert numbers already typed.
A12: THEN WORK THROUGH THESE TABS IN ORDER
A13: Step | B13: Tab | C13: What to do
A14: 1 | B14: Room Area | C14: Enter each room's size.
A15: 2 | B15: Paint & Tiles | C15: Enter each room once, with its doors and windows.
A16: 3 | B16: Concrete | C16: Enter slabs, beams, columns and footings. Use the mix your engineer specifies.
A17: 4 | B17: Bricks & Blocks | C17: Enter wall lengths, heights and openings.
A18: 5 | B18: Steel | C18: Enter bar sizes and counts from your structural drawings.
A19: 6 | B19: Rates | C19: Type in your own quotes. Costs show as zero until you do.
A20: 7 | B20: Cost Estimate | C20: Add costs the calculators don't cover, and tag each with a stage.
A21: 8 | B21: Stage Budget and Order List | C21: Check spend by stage and see what to buy.
A23: Yellow cells are yours to change. Green cells calculate automatically.

Sheet Setup
A1: SETUP
A2: Enter this once for each project. Every calculator uses these settings.
A3: EXAMPLE RENOVATION: placeholder rates and quantities. These totals are NOT a real estimate.
A4: Setting | B4: Your entry | C4: What to enter
A5: Project name | B5: EXAMPLE RENOVATION: kitchen, bathroom and bedroom, 1,000 sq ft flat, Chennai | C5: Any name you like
A6: Client / owner | B6: Sample client | C6: Name of the homeowner or client (used on the quotation)
A7: City | B7: Chennai | C7: For your reference
A8: Project type | B8: Renovation | C8: For your reference. It doesn't change calculations.
A9: Units | B9: ='Quick Start'!B10 | C9: Feet or Metres. Set this before you measure anything. Changing it does not convert numbers already typed.
A10: Built-up area | B10: 1000 | C10: In the units you chose (sq ft or sq m). Total floor area.
A11: Target budget (₹) | B11: 400000 | C11: The most you plan to spend
A12: Contingency (%) | B12: 0.1 | C12: Extra money for unknowns. Added to the estimate.
A13: GST on works (%) | B13: 0 | C13: Leave at 0% until your accountant confirms the rate for your contract.
A14: Start date | B14: 46327 | C14: Drives the start of the Timeline.
A16: AUTOMATIC CONVERSIONS (do not edit)
A17: Length factor to feet | B17: =IF(B9="Metres",3.28084,1)
A18: Area factor to sq ft | B18: =IF(B9="Metres",10.7639,1)
A19: Built-up area in sq ft | B19: =B10*B18

Sheet Room Area
A1: ROOM AREA
A2: Type the size of each room. The areas add up automatically.
A3: EXAMPLE RENOVATION: placeholder rates and quantities. These totals are NOT a real estimate.
A5: Room / space | B5: ="Length ("&IF(Setup!$B$9="Metres","m","ft")&")" | C5: ="Width ("&IF(Setup!$B$9="Metres","m","ft")&")" | D5: Count (identical rooms) | E5: ="Area ("&IF(Setup!$B$9="Metres","sq m","sq ft")&")" | F5: Area (sq m)
A6: Kitchen | B6: 10 | C6: 9 | D6: 1 | E6: =IF(OR(B6="",C6=""),0,B6*C6*IF(D6="",1,D6)*Setup!$B$18) | F6: =E6/10.7639
A7: Bedroom | B7: 12 | C7: 11 | D7: 1 | E7: =IF(OR(B7="",C7=""),0,B7*C7*IF(D7="",1,D7)*Setup!$B$18) | F7: =E7/10.7639
A8: Bathroom | B8: 6 | C8: 5 | D8: 1 | E8: =IF(OR(B8="",C8=""),0,B8*C8*IF(D8="",1,D8)*Setup!$B$18) | F8: =E8/10.7639
E9: =IF(OR(B9="",C9=""),0,B9*C9*IF(D9="",1,D9)*Setup!$B$18) | F9: =E9/10.7639
E10: =IF(OR(B10="",C10=""),0,B10*C10*IF(D10="",1,D10)*Setup!$B$18) | F10: =E10/10.7639
E11: =IF(OR(B11="",C11=""),0,B11*C11*IF(D11="",1,D11)*Setup!$B$18) | F11: =E11/10.7639
E12: =IF(OR(B12="",C12=""),0,B12*C12*IF(D12="",1,D12)*Setup!$B$18) | F12: =E12/10.7639
E13: =IF(OR(B13="",C13=""),0,B13*C13*IF(D13="",1,D13)*Setup!$B$18) | F13: =E13/10.7639
E14: =IF(OR(B14="",C14=""),0,B14*C14*IF(D14="",1,D14)*Setup!$B$18) | F14: =E14/10.7639
E15: =IF(OR(B15="",C15=""),0,B15*C15*IF(D15="",1,D15)*Setup!$B$18) | F15: =E15/10.7639
E16: =IF(OR(B16="",C16=""),0,B16*C16*IF(D16="",1,D16)*Setup!$B$18) | F16: =E16/10.7639
E17: =IF(OR(B17="",C17=""),0,B17*C17*IF(D17="",1,D17)*Setup!$B$18) | F17: =E17/10.7639
A18: TOTAL | E18: =SUM(E6:E17) | F18: =SUM(F6:F17)
A20: Enter up to 12 rooms. Paint & Tiles reads these rooms, so enter them once here.
A21: Tip: for 4 identical bathrooms, type 4 in Count. Count multiplies walls and floor.

Sheet Earthwork
A1: EARTHWORK
A2: Soil to dig for foundations, trenches and pits. Dimensions follow your Units setting.
A3: EXAMPLE RENOVATION: placeholder rates and quantities. These totals are NOT a real estimate.
A5: Item | B5: ="Length ("&IF(Setup!$B$9="Metres","m","ft")&")" | C5: ="Width ("&IF(Setup!$B$9="Metres","m","ft")&")" | D5: ="Depth ("&IF(Setup!$B$9="Metres","m","ft")&")" | E5: Count | F5: Volume (cu ft) | G5: Volume (m³)
F6: =IF(OR(B6="",C6="",D6=""),0,B6*C6*D6*IF(E6="",1,E6)*Setup!$B$17^3) | G6: =F6/35.3147
F7: =IF(OR(B7="",C7="",D7=""),0,B7*C7*D7*IF(E7="",1,E7)*Setup!$B$17^3) | G7: =F7/35.3147
F8: =IF(OR(B8="",C8="",D8=""),0,B8*C8*D8*IF(E8="",1,E8)*Setup!$B$17^3) | G8: =F8/35.3147
F9: =IF(OR(B9="",C9="",D9=""),0,B9*C9*D9*IF(E9="",1,E9)*Setup!$B$17^3) | G9: =F9/35.3147
F10: =IF(OR(B10="",C10="",D10=""),0,B10*C10*D10*IF(E10="",1,E10)*Setup!$B$17^3) | G10: =F10/35.3147
F11: =IF(OR(B11="",C11="",D11=""),0,B11*C11*D11*IF(E11="",1,E11)*Setup!$B$17^3) | G11: =F11/35.3147
F12: =IF(OR(B12="",C12="",D12=""),0,B12*C12*D12*IF(E12="",1,E12)*Setup!$B$17^3) | G12: =F12/35.3147
F13: =IF(OR(B13="",C13="",D13=""),0,B13*C13*D13*IF(E13="",1,E13)*Setup!$B$17^3) | G13: =F13/35.3147
F14: =SUM(F6:F13) | G14: =SUM(G6:G13)
A17: Extra for over-digging and working space (%) | B17: 0.1
A18: Total to excavate (cu ft) | B18: =F14*(1+B17)
A19: Total to excavate (m³) | B19: =B18/35.3147
A21: COST (₹)
A22: Excavation cost (₹) | B22: =B18*Rates!$C$16
A24: Not included: backfilling, soil removal by lorry, dewatering and rock. Get a separate quote for soil removal.
A25: Excavation rate is on the Rates tab (row 16). It is a placeholder until you enter your own quote.

Sheet Paint & Tiles
A1: PAINT & TILES
A2: Enter each room once. Paint and tile totals add up all rooms. Dimensions follow your Units setting.
A3: EXAMPLE RENOVATION: placeholder rates and quantities. These totals are NOT a real estimate.
A4: ROOM DATA (walls for paint, floor for tiles)
A5: Room | B5: ="Length ("&IF(Setup!$B$9="Metres","m","ft")&")" | C5: ="Width ("&IF(Setup!$B$9="Metres","m","ft")&")" | D5: ="Height ("&IF(Setup!$B$9="Metres","m","ft")&")" | E5: Doors (count) | F5: Windows (count) | G5: ="Net wall area to paint ("&IF(Setup!$B$9="Metres","sq m","sq ft")&")" | H5: ="Floor area ("&IF(Setup!$B$9="Metres","sq m","sq ft")&")" | I5: Notes | J5: Count (from Room Area)
A6: =IF('Room Area'!A6="","",'Room Area'!A6) | B6: =IF('Room Area'!B6="","",'Room Area'!B6) | C6: =IF('Room Area'!C6="","",'Room Area'!C6) | D6: 10 | E6: 1 | F6: 1 | G6: =IF(OR(B6="",C6="",D6=""),0,MAX(0,2*(B6+C6)*D6-(IF(E6="",0,E6)*$B$21*$B$22+IF(F6="",0,F6)*$B$23*$B$24))*Setup!$B$18*J6) | H6: =IF(OR(B6="",C6=""),0,B6*C6*Setup!$B$18*J6) | J6: =IF('Room Area'!D6="",1,'Room Area'!D6)
A7: =IF('Room Area'!A7="","",'Room Area'!A7) | B7: =IF('Room Area'!B7="","",'Room Area'!B7) | C7: =IF('Room Area'!C7="","",'Room Area'!C7) | D7: 10 | E7: 1 | F7: 1 | G7: =IF(OR(B7="",C7="",D7=""),0,MAX(0,2*(B7+C7)*D7-(IF(E7="",0,E7)*$B$21*$B$22+IF(F7="",0,F7)*$B$23*$B$24))*Setup!$B$18*J7) | H7: =IF(OR(B7="",C7=""),0,B7*C7*Setup!$B$18*J7) | J7: =IF('Room Area'!D7="",1,'Room Area'!D7)
A8: =IF('Room Area'!A8="","",'Room Area'!A8) | B8: =IF('Room Area'!B8="","",'Room Area'!B8) | C8: =IF('Room Area'!C8="","",'Room Area'!C8) | D8: 8 | E8: 1 | F8: 0 | G8: =IF(OR(B8="",C8="",D8=""),0,MAX(0,2*(B8+C8)*D8-(IF(E8="",0,E8)*$B$21*$B$22+IF(F8="",0,F8)*$B$23*$B$24))*Setup!$B$18*J8) | H8: =IF(OR(B8="",C8=""),0,B8*C8*Setup!$B$18*J8) | J8: =IF('Room Area'!D8="",1,'Room Area'!D8)
A9: =IF('Room Area'!A9="","",'Room Area'!A9) | B9: =IF('Room Area'!B9="","",'Room Area'!B9) | C9: =IF('Room Area'!C9="","",'Room Area'!C9) | G9: =IF(OR(B9="",C9="",D9=""),0,MAX(0,2*(B9+C9)*D9-(IF(E9="",0,E9)*$B$21*$B$22+IF(F9="",0,F9)*$B$23*$B$24))*Setup!$B$18*J9) | H9: =IF(OR(B9="",C9=""),0,B9*C9*Setup!$B$18*J9) | J9: =IF('Room Area'!D9="",1,'Room Area'!D9)
A10: =IF('Room Area'!A10="","",'Room Area'!A10) | B10: =IF('Room Area'!B10="","",'Room Area'!B10) | C10: =IF('Room Area'!C10="","",'Room Area'!C10) | G10: =IF(OR(B10="",C10="",D10=""),0,MAX(0,2*(B10+C10)*D10-(IF(E10="",0,E10)*$B$21*$B$22+IF(F10="",0,F10)*$B$23*$B$24))*Setup!$B$18*J10) | H10: =IF(OR(B10="",C10=""),0,B10*C10*Setup!$B$18*J10) | J10: =IF('Room Area'!D10="",1,'Room Area'!D10)
A11: =IF('Room Area'!A11="","",'Room Area'!A11) | B11: =IF('Room Area'!B11="","",'Room Area'!B11) | C11: =IF('Room Area'!C11="","",'Room Area'!C11) | G11: =IF(OR(B11="",C11="",D11=""),0,MAX(0,2*(B11+C11)*D11-(IF(E11="",0,E11)*$B$21*$B$22+IF(F11="",0,F11)*$B$23*$B$24))*Setup!$B$18*J11) | H11: =IF(OR(B11="",C11=""),0,B11*C11*Setup!$B$18*J11) | J11: =IF('Room Area'!D11="",1,'Room Area'!D11)
A12: =IF('Room Area'!A12="","",'Room Area'!A12) | B12: =IF('Room Area'!B12="","",'Room Area'!B12) | C12: =IF('Room Area'!C12="","",'Room Area'!C12) | G12: =IF(OR(B12="",C12="",D12=""),0,MAX(0,2*(B12+C12)*D12-(IF(E12="",0,E12)*$B$21*$B$22+IF(F12="",0,F12)*$B$23*$B$24))*Setup!$B$18*J12) | H12: =IF(OR(B12="",C12=""),0,B12*C12*Setup!$B$18*J12) | J12: =IF('Room Area'!D12="",1,'Room Area'!D12)
A13: =IF('Room Area'!A13="","",'Room Area'!A13) | B13: =IF('Room Area'!B13="","",'Room Area'!B13) | C13: =IF('Room Area'!C13="","",'Room Area'!C13) | G13: =IF(OR(B13="",C13="",D13=""),0,MAX(0,2*(B13+C13)*D13-(IF(E13="",0,E13)*$B$21*$B$22+IF(F13="",0,F13)*$B$23*$B$24))*Setup!$B$18*J13) | H13: =IF(OR(B13="",C13=""),0,B13*C13*Setup!$B$18*J13) | J13: =IF('Room Area'!D13="",1,'Room Area'!D13)
A14: =IF('Room Area'!A14="","",'Room Area'!A14) | B14: =IF('Room Area'!B14="","",'Room Area'!B14) | C14: =IF('Room Area'!C14="","",'Room Area'!C14) | G14: =IF(OR(B14="",C14="",D14=""),0,MAX(0,2*(B14+C14)*D14-(IF(E14="",0,E14)*$B$21*$B$22+IF(F14="",0,F14)*$B$23*$B$24))*Setup!$B$18*J14) | H14: =IF(OR(B14="",C14=""),0,B14*C14*Setup!$B$18*J14) | J14: =IF('Room Area'!D14="",1,'Room Area'!D14)
A15: =IF('Room Area'!A15="","",'Room Area'!A15) | B15: =IF('Room Area'!B15="","",'Room Area'!B15) | C15: =IF('Room Area'!C15="","",'Room Area'!C15) | G15: =IF(OR(B15="",C15="",D15=""),0,MAX(0,2*(B15+C15)*D15-(IF(E15="",0,E15)*$B$21*$B$22+IF(F15="",0,F15)*$B$23*$B$24))*Setup!$B$18*J15) | H15: =IF(OR(B15="",C15=""),0,B15*C15*Setup!$B$18*J15) | J15: =IF('Room Area'!D15="",1,'Room Area'!D15)
A16: =IF('Room Area'!A16="","",'Room Area'!A16) | B16: =IF('Room Area'!B16="","",'Room Area'!B16) | C16: =IF('Room Area'!C16="","",'Room Area'!C16) | G16: =IF(OR(B16="",C16="",D16=""),0,MAX(0,2*(B16+C16)*D16-(IF(E16="",0,E16)*$B$21*$B$22+IF(F16="",0,F16)*$B$23*$B$24))*Setup!$B$18*J16) | H16: =IF(OR(B16="",C16=""),0,B16*C16*Setup!$B$18*J16) | J16: =IF('Room Area'!D16="",1,'Room Area'!D16)
A17: =IF('Room Area'!A17="","",'Room Area'!A17) | B17: =IF('Room Area'!B17="","",'Room Area'!B17) | C17: =IF('Room Area'!C17="","",'Room Area'!C17) | G17: =IF(OR(B17="",C17="",D17=""),0,MAX(0,2*(B17+C17)*D17-(IF(E17="",0,E17)*$B$21*$B$22+IF(F17="",0,F17)*$B$23*$B$24))*Setup!$B$18*J17) | H17: =IF(OR(B17="",C17=""),0,B17*C17*Setup!$B$18*J17) | J17: =IF('Room Area'!D17="",1,'Room Area'!D17)
A18: TOTAL | G18: =SUM(G6:G17) | H18: =SUM(H6:H17)
A20: OPENINGS (standard size, applies to every room)
A21: ="Door width ("&IF(Setup!$B$9="Metres","m","ft")&")" | B21: 3
A22: ="Door height ("&IF(Setup!$B$9="Metres","m","ft")&")" | B22: 7
A23: ="Window width ("&IF(Setup!$B$9="Metres","m","ft")&")" | B23: 4
A24: ="Window height ("&IF(Setup!$B$9="Metres","m","ft")&")" | B24: 4
A26: PAINT SETTINGS
A27: Number of coats | B27: 2
A28: Paint coverage (sq ft per litre) | B28: 100
A29: Extra for waste (%) | B29: 0.1
A31: TILE SETTINGS
A32: Tile length (mm) | B32: 600
A33: Tile width (mm) | B33: 600
A34: Extra for cutting and breakage (%) | B34: 0.1
A36: RESULTS
A37: Net wall area to paint (sq ft) | B37: =G18
A38: Litres of paint to buy | B38: =IF(B37=0,0,ROUNDUP(B37*B27/B28*(1+B29),0))
A39: Paint cost (₹) | B39: =B38*Rates!$C$12
A40: Floor area to tile (sq ft) | B40: =H18
A41: Tiles to buy | B41: =IF(B40=0,0,ROUNDUP(B40*(1+B34)/((B32/304.8)*(B33/304.8)),0))
A42: Tile cost (₹) | B42: =B40*(1+B34)*Rates!$C$13
A44: Tip: enter a row per room. Leave unused rows blank. Count the openings in each room.
A46: OPENINGS TOTAL (linked to Bricks & Blocks)
...

Sheet Exterior & Roof
A1: EXTERIOR PAINT & ROOF
A2: Outside walls and a flat roof. Dimensions follow your Units setting. Pitched roofs are not covered here.
A3: EXAMPLE RENOVATION: placeholder rates and quantities. These totals are NOT a real estimate.
A4: EXTERIOR WALLS
A5: ="Building perimeter (outside wall length) ("&IF(Setup!$B$9="Metres","m","ft")&")"
A6: ="Outside wall height ("&IF(Setup!$B$9="Metres","m","ft")&")"
A7: ="Less doors and windows on outside walls ("&IF(Setup!$B$9="Metres","sq m","sq ft")&")"
A8: ="External wall area to paint ("&IF(Setup!$B$9="Metres","sq m","sq ft")&")" | B8: =IF(OR(B5="",B6=""),0,MAX(0,B5*B6-IF(B7="",0,B7))*Setup!$B$18)
A9: Number of coats | B9: 2
A10: Paint coverage (sq ft per litre) | B10: ='Paint & Tiles'!B28
A11: Extra for waste (%) | B11: ='Paint & Tiles'!B29
A12: Litres of exterior paint to buy | B12: =IF(B8=0,0,ROUNDUP(B8*B9/B10*(1+B11),0))
A13: Exterior paint cost (₹) | B13: =B12*Rates!$C$17
A14: Exterior painting labour (₹) | B14: =B8*Rates!$C$20
A16: FLAT ROOF (terrace)
A17: ="Roof area (plan area of a flat roof) ("&IF(Setup!$B$9="Metres","sq m","sq ft")&")"
A18: Roof waterproofing cost (₹) | B18: =B17*Setup!$B$18*Rates!$C$18
A20: TOTAL
A21: Exterior paint and roof total (₹) | B21: =B13+B14+B18
A23: Enter the outside wall length and height. Openings are subtracted. Two coats is a common default. Check with your painter.
A24: Roof: flat roofs only. A sloped roof needs its own quote for sheets or tiles.
A25: The roof rate should cover both material and labour. Use your own quote.
A26: Not included: scaffolding, cleaning, crack repair, and external plaster.

Sheet Concrete
A1: CONCRETE
A2: Enter the size of each concrete item. Mix quantities and cost are worked out for you.
A3: EXAMPLE RENOVATION: placeholder rates and quantities. These totals are NOT a real estimate.
A5: Item | B5: ="Length ("&IF(Setup!$B$9="Metres","m","ft")&")" | C5: ="Width ("&IF(Setup!$B$9="Metres","m","ft")&")" | D5: ="Depth / height ("&IF(Setup!$B$9="Metres","m","ft")&")" | E5: Count | F5: Volume (cu ft) | G5: Volume (m³)
F6: =IF(OR(B6="",C6="",D6=""),0,B6*C6*D6*IF(E6="",1,E6)*Setup!$B$17^3) | G6: =F6/35.3147
F7: =IF(OR(B7="",C7="",D7=""),0,B7*C7*D7*IF(E7="",1,E7)*Setup!$B$17^3) | G7: =F7/35.3147
F8: =IF(OR(B8="",C8="",D8=""),0,B8*C8*D8*IF(E8="",1,E8)*Setup!$B$17^3) | G8: =F8/35.3147
F9: =IF(OR(B9="",C9="",D9=""),0,B9*C9*D9*IF(E9="",1,E9)*Setup!$B$17^3) | G9: =F9/35.3147
F10: =IF(OR(B10="",C10="",D10=""),0,B10*C10*D10*IF(E10="",1,E10)*Setup!$B$17^3) | G10: =F10/35.3147
F11: =IF(OR(B11="",C11="",D11=""),0,B11*C11*D11*IF(E11="",1,E11)*Setup!$B$17^3) | G11: =F11/35.3147
F12: =IF(OR(B12="",C12="",D12=""),0,B12*C12*D12*IF(E12="",1,E12)*Setup!$B$17^3) | G12: =F12/35.3147
F13: =IF(OR(B13="",C13="",D13=""),0,B13*C13*D13*IF(E13="",1,E13)*Setup!$B$17^3) | G13: =F13/35.3147
F14: =SUM(F6:F13) | G14: =SUM(G6:G13)
A17: Cement parts | B17: 1 | C17: 1 : 2 : 4 is an example mix only. The grade and mix come from your engineer's specification, which always takes priority.
A18: Sand parts | B18: 2
A19: Aggregate parts | B19: 4
A20: Dry volume factor (wet to dry) | B20: 1.54
A21: Dry volume (cu ft) | B21: =F14*B20
A22: Total parts | B22: =SUM(B17:B19)
A24: MATERIALS NEEDED (before extra wastage)
A25: Cement bags (50 kg) | B25: =IF(B22=0,0,ROUNDUP(B21*B17/B22/Assumptions!$B$11,0))
A26: Sand (cu ft) | B26: =IF(B22=0,0,B21*B18/B22)
A27: Aggregate (cu ft) | B27: =IF(B22=0,0,B21*B19/B22)
A29: COST (₹)
A30: Cement | B30: =B25*Rates!$C$6
A31: Sand | B31: =B26*Rates!$C$7
A32: Aggregate | B32: =B27*Rates!$C$8
A33: Labour | B33: =F14*Rates!$C$14
B34: =SUM(B30:B33)

Sheet Bricks & Blocks
A1: BRICKS & BLOCKS
A2: How many bricks or blocks each wall needs.
A3: EXAMPLE RENOVATION: placeholder rates and quantities. These totals are NOT a real estimate.
A5: Wall | B5: ="Length ("&IF(Setup!$B$9="Metres","m","ft")&")" | C5: ="Height ("&IF(Setup!$B$9="Metres","m","ft")&")" | D5: ="Openings (doors & windows) ("&IF(Setup!$B$9="Metres","sq m","sq ft")&")" | E5: Net area (sq ft) | F5: Thickness (mm) | G5: Volume (m³)
D6: ='Paint & Tiles'!B47/Setup!$B$18 | E6: =MAX(0,B6*C6-D6)*Setup!$B$18 | G6: =E6/10.7639*F6/1000
D7: ='Paint & Tiles'!B48/Setup!$B$18 | E7: =MAX(0,B7*C7-D7)*Setup!$B$18 | G7: =E7/10.7639*F7/1000
E8: =MAX(0,B8*C8-D8)*Setup!$B$18 | G8: =E8/10.7639*F8/1000
E9: =MAX(0,B9*C9-D9)*Setup!$B$18 | G9: =E9/10.7639*F9/1000
E10: =MAX(0,B10*C10-D10)*Setup!$B$18 | G10: =E10/10.7639*F10/1000
E11: =SUM(E6:E10) | G11: =SUM(G6:G10)
A17: AAC block height (mm) | B17: 200
A18: AAC block thickness (mm) | B18: 200
A20: RESULTS
A21: Red clay bricks needed (includes breakage) | B21: =ROUNDUP(G11*B14*(1+B15),0)
A22: Brick cost (₹) | B22: =B21*Rates!$C$9
A23: AAC blocks needed (alternative to bricks) | B23: =IF(B16*B17*B18=0,0,ROUNDUP(G11*1000000000/(B16*B17*B18)*(1+B15),0))
A24: AAC block cost (₹) | B24: =B23*Rates!$C$10
A25: Masonry labour (₹) | B25: =E11*Rates!$C$15
A26: TOTAL MASONRY COST, brick option (₹) | B26: =B22+B25
A28: Tip: use bricks or AAC blocks, not both. Mortar is not included.

Sheet Plaster
A1: PLASTER
A2: Cement and sand for plaster on walls and ceilings. Areas come from the Paint & Tiles tab. Assumptions are marked for checking.
A3: EXAMPLE RENOVATION: placeholder rates and quantities. These totals are NOT a real estimate.
A4: AREA (from Paint & Tiles)
A5: Wall area to plaster (sq ft) | B5: ='Paint & Tiles'!G18
A6: Ceiling area to plaster (sq ft) | B6: ='Paint & Tiles'!H18
A7: Total area to plaster (sq ft) | B7: =B5+B6
A9: ASSUMPTIONS (confirm with your mason or engineer)
A10: Plaster thickness (mm) | B10: 12
A11: Dry volume factor (wet to dry) | B11: 1.27
A12: Cement parts | B12: 1
A13: Sand parts | B13: 6
A14: Extra for wastage (%) | B14: 0.1
A16: RESULTS
A17: Wet volume (cu ft) | B17: =B7*B10/304.8
A18: Dry volume incl. wastage (cu ft) | B18: =B17*B11*(1+B14)
A19: Cement bags (50 kg) | B19: =IF(B12+B13=0,0,ROUNDUP(B18*B12/(B12+B13)/Assumptions!$B$11,0))
A20: Sand (cu ft) | B20: =IF(B12+B13=0,0,B18*B13/(B12+B13))
A22: COST (₹)
A23: Cement | B23: =B19*Rates!$C$6
A24: Sand | B24: =B20*Rates!$C$7
A25: TOTAL PLASTER MATERIAL COST | B25: =B23+B24
A26: Plaster labour (₹) | B26: =B7*Rates!$C$19
A27: Plaster labour is included at the rate on the Rates tab. Check the rate with your mason.
A28: Wastage is included once here. The Order List does not add more for plaster sand.
A29: Area is the interior wall area from Paint & Tiles plus the floor area as ceilings. External wall faces are NOT included.

Sheet Steel
A1: STEEL
A2: Steel weight from bar size and number of bars. Bar length is always in metres.
A3: EXAMPLE RENOVATION: placeholder rates and quantities. These totals are NOT a real estimate.
A5: Bar diameter (mm) | B5: Length per bar (m) | C5: Number of bars | D5: Weight (kg) | E5: Weight (tonnes)
D6: =IF(A6="",0,A6^2/Assumptions!$B$21*B6*C6) | E6: =D6/1000
D7: =IF(A7="",0,A7^2/Assumptions!$B$21*B7*C7) | E7: =D7/1000
D8: =IF(A8="",0,A8^2/Assumptions!$B$21*B8*C8) | E8: =D8/1000
D9: =IF(A9="",0,A9^2/Assumptions!$B$21*B9*C9) | E9: =D9/1000
D10: =IF(A10="",0,A10^2/Assumptions!$B$21*B10*C10) | E10: =D10/1000
D11: =IF(A11="",0,A11^2/Assumptions!$B$21*B11*C11) | E11: =D11/1000
D12: =SUM(D6:D11) | E12: =SUM(E6:E11)
D14: =D12*Rates!$C$11

Sheet Services
A1: SERVICES
A2: Count the points and fittings, then enter a rate per point. Blank counts or rates show zero.
A3: EXAMPLE RENOVATION: placeholder rates and quantities. These totals are NOT a real estimate.
A5: Item | B5: Count | C5: Rate per item (₹, you enter) | D5: Cost (₹)
A6: Water point for WC | B6: 1 | C6: 2500 | D6: =IF(OR(B6="",C6=""),0,B6*C6)
A7: Water point for wash basin | B7: 1 | C7: 2500 | D7: =IF(OR(B7="",C7=""),0,B7*C7)
A8: Shower point | B8: 1 | C8: 2500 | D8: =IF(OR(B8="",C8=""),0,B8*C8)
A9: Kitchen sink point | B9: 0 | C9: 2500 | D9: =IF(OR(B9="",C9=""),0,B9*C9)
A10: Washing machine point | B10: 0 | C10: 2500 | D10: =IF(OR(B10="",C10=""),0,B10*C10)
A11: Overhead tank connection | B11: 0 | C11: 2500 | D11: =IF(OR(B11="",C11=""),0,B11*C11)
A12: Water heater point | B12: 0 | C12: 2500 | D12: =IF(OR(B12="",C12=""),0,B12*C12)
A13: PLUMBING TOTAL | D13: =SUM(D6:D12)
A14: Electrical points
A15: Light points | B15: 8 | C15: 1200 | D15: =IF(OR(B15="",C15=""),0,B15*C15)
A16: Fan points | B16: 2 | C16: 1200 | D16: =IF(OR(B16="",C16=""),0,B16*C16)
A17: 6 A plug points | B17: 6 | C17: 1200 | D17: =IF(OR(B17="",C17=""),0,B17*C17)
A18: 16 A plug points | B18: 1 | C18: 1200 | D18: =IF(OR(B18="",C18=""),0,B18*C18)
A19: AC points | B19: 0 | C19: 1200 | D19: =IF(OR(B19="",C19=""),0,B19*C19)
A20: Geyser point | B20: 0 | C20: 1200 | D20: =IF(OR(B20="",C20=""),0,B20*C20)
A21: TV or data points | B21: 0 | C21: 1200 | D21: =IF(OR(B21="",C21=""),0,B21*C21)
A22: Distribution board | B22: 0 | C22: 1200 | D22: =IF(OR(B22="",C22=""),0,B22*C22)
A23: ELECTRICAL TOTAL | D23: =SUM(D15:D22)
A25: Pipes, wires and conduits are included in the rate per point if your rate covers them. Confirm with your plumber or electrician.

Sheet Cost Estimate
A1: COST ESTIMATE
A2: Full estimate. Calculator items fill in automatically. Enter the rest yourself and tag each line with a stage.
A3: EXAMPLE RENOVATION: placeholder rates and quantities. These totals are NOT a real estimate.
A5: Cost item | B5: Source | C5: Estimated (₹) | D5: Actual spent (₹) | E5: Difference (₹) | F5: % of estimate spent | G5: Status | H5: Stage
A6: Site preparation & foundation (excavation, clearing) | B6: Auto | C6: =Earthwork!B22 | E6: =C6-D6 | F6: =IF(C6=0,"",D6/C6) | G6: Planned | H6: Site preparation & foundation
A7: Concrete & RCC | B7: Auto | C7: =Concrete!B34 | E7: =C7-D7 | F7: =IF(C7=0,"",D7/C7) | G7: Planned | H7: Structure (concrete & steel)
A8: Steel reinforcement | B8: Auto | C8: =Steel!D14 | E8: =C8-D8 | F8: =IF(C8=0,"",D8/C8) | G8: Planned | H8: Structure (concrete & steel)
A9: Brickwork & masonry labour | B9: Auto | C9: ='Bricks & Blocks'!B26 | E9: =C9-D9 | F9: =IF(C9=0,"",D9/C9) | G9: Planned | H9: Masonry (walls)
A10: Plaster (walls and ceilings, materials and labour) | B10: Auto | C10: =Plaster!B25+Plaster!B26 | E10: =C10-D10 | F10: =IF(C10=0,"",D10/C10) | G10: Planned | H10: Masonry (walls)
A11: Floor tiles (materials and laying labour) | B11: Auto | C11: ='Paint & Tiles'!B42+'Paint & Tiles'!B40*Rates!$C$21 | E11: =C11-D11 | F11: =IF(C11=0,"",D11/C11) | G11: Planned | H11: Flooring
A12: Interior paint (materials and labour) | B12: Auto | C12: ='Paint & Tiles'!B39+'Paint & Tiles'!G18*Rates!$C$20 | E12: =C12-D12 | F12: =IF(C12=0,"",D12/C12) | G12: Planned | H12: Painting
A13: External paint (materials and labour) | B13: Auto | C13: ='Exterior & Roof'!B13+'Exterior & Roof'!B14 | E13: =C13-D13 | F13: =IF(C13=0,"",D13/C13) | G13: Planned | H13: Painting
A14: Doors | B14: Enter | E14: =C14-D14 | F14: =IF(C14=0,"",D14/C14) | G14: Planned | H14: Doors, windows & fittings
A15: Windows | B15: Enter | E15: =C15-D15 | F15: =IF(C15=0,"",D15/C15) | G15: Planned | H15: Doors, windows & fittings
A16: Plumbing fittings and pipes | B16: Auto | C16: =Services!D13 | E16: =C16-D16 | F16: =IF(C16=0,"",D16/C16) | G16: Planned | H16: Plumbing & electrical
A17: Electrical wiring and fittings | B17: Auto | C17: =Services!D23 | E17: =C17-D17 | F17: =IF(C17=0,"",D17/C17) | G17: Planned | H17: Plumbing & electrical
A18: Kitchen counter and cabinets | B18: Enter | E18: =C18-D18 | F18: =IF(C18=0,"",D18/C18) | G18: Planned | H18: Kitchen & bathrooms
A19: Sanitaryware and taps | B19: Enter | E19: =C19-D19 | F19: =IF(C19=0,"",D19/C19) | G19: Planned | H19: Kitchen & bathrooms
A20: Waterproofing (bathrooms, kitchen, wet areas) | B20: Enter | E20: =C20-D20 | F20: =IF(C20=0,"",D20/C20) | G20: Planned | H20: Kitchen & bathrooms
A21: Roof waterproofing (flat roof) | B21: Auto | C21: ='Exterior & Roof'!B18 | E21: =C21-D21 | F21: =IF(C21=0,"",D21/C21) | G21: Planned | H21: Structure (concrete & steel)
A22: General labour (not in calculators) | B22: Enter | E22: =C22-D22 | F22: =IF(C22=0,"",D22/C22) | G22: Planned | H22: Approvals, fees & other
A23: Transport and unloading | B23: Enter | E23: =C23-D23 | F23: =IF(C23=0,"",D23/C23) | G23: Planned | H23: Approvals, fees & other
A24: Approvals and fees (total from Permits tab) | B24: Auto | C24: =Permits!I26 | E24: =C24-D24 | F24: =IF(C24=0,"",D24/C24) | G24: Planned | H24: Approvals, fees & other
A25: Other | B25: Enter | E25: =C25-D25 | F25: =IF(C25=0,"",D25/C25) | G25: Planned | H25: Approvals, fees & other
A26: SUBTOTAL (before contingency and GST) | C26: =SUM(C6:C25) | D26: =SUM(D6:D25) | E26: =C26-D26
A27: Contingency | C27: =C26*Setup!$B$12
A28: GST on works | C28: =(C26+C27)*Setup!$B$13
A29: TOTAL ESTIMATE | C29: =C26+C27+C28 | D29: =D26
A30: Target budget | C30: =Setup!$B$11
A31: Headroom (positive = under budget) | C31: =C30-C29
A32: Cost per sq ft (₹) | C32: =IF(Setup!$B$19=0,0,C29/Setup!$B$19)
A34: =IF(COUNTBLANK(Rates!C6:C21)>0,"Warning: "&COUNTBLANK(Rates!C6:C21)&" rate(s) are blank on the Rates tab, so those costs show as zero.","All rates entered.")

Sheet Room Costs
A1: ROOM COSTS
A2: Paint and tile cost for each room. Structure, masonry, plumbing and electrical are not assigned to rooms.
A3: EXAMPLE RENOVATION: placeholder rates and quantities. These totals are NOT a real estimate.
A5: Room | B5: ="Floor area ("&IF(Setup!$B$9="Metres","sq m","sq ft")&")" | C5: ="Net wall area ("&IF(Setup!$B$9="Metres","sq m","sq ft")&")" | D5: Paint cost (₹) | E5: Tile cost (₹) | F5: Paint and tiles (₹) | G5: Share of paint and tiles
A6: ='Paint & Tiles'!A6 | B6: ='Paint & Tiles'!H6 | C6: ='Paint & Tiles'!G6 | D6: =C6*'Paint & Tiles'!$B$27/'Paint & Tiles'!$B$28*(1+'Paint & Tiles'!$B$29)*Rates!$C$12 | E6: =B6*(1+'Paint & Tiles'!$B$34)*Rates!$C$13 | F6: =D6+E6 | G6: =IF($F$20=0,"",F6/$F$20)
A7: ='Paint & Tiles'!A7 | B7: ='Paint & Tiles'!H7 | C7: ='Paint & Tiles'!G7 | D7: =C7*'Paint & Tiles'!$B$27/'Paint & Tiles'!$B$28*(1+'Paint & Tiles'!$B$29)*Rates!$C$12 | E7: =B7*(1+'Paint & Tiles'!$B$34)*Rates!$C$13 | F7: =D7+E7 | G7: =IF($F$20=0,"",F7/$F$20)
A8: ='Paint & Tiles'!A8 | B8: ='Paint & Tiles'!H8 | C8: ='Paint & Tiles'!G8 | D8: =C8*'Paint & Tiles'!$B$27/'Paint & Tiles'!$B$28*(1+'Paint & Tiles'!$B$29)*Rates!$C$12 | E8: =B8*(1+'Paint & Tiles'!$B$34)*Rates!$C$13 | F8: =D8+E8 | G8: =IF($F$20=0,"",F8/$F$20)
A9: ='Paint & Tiles'!A9 | B9: ='Paint & Tiles'!H9 | C9: ='Paint & Tiles'!G9 | D9: =C9*'Paint & Tiles'!$B$27/'Paint & Tiles'!$B$28*(1+'Paint & Tiles'!$B$29)*Rates!$C$12 | E9: =B9*(1+'Paint & Tiles'!$B$34)*Rates!$C$13 | F9: =D9+E9 | G9: =IF($F$20=0,"",F9/$F$20)
A10: ='Paint & Tiles'!A10 | B10: ='Paint & Tiles'!H10 | C10: ='Paint & Tiles'!G10 | D10: =C10*'Paint & Tiles'!$B$27/'Paint & Tiles'!$B$28*(1+'Paint & Tiles'!$B$29)*Rates!$C$12 | E10: =B10*(1+'Paint & Tiles'!$B$34)*Rates!$C$13 | F10: =D10+E10 | G10: =IF($F$20=0,"",F10/$F$20)
A11: ='Paint & Tiles'!A11 | B11: ='Paint & Tiles'!H11 | C11: ='Paint & Tiles'!G11 | D11: =C11*'Paint & Tiles'!$B$27/'Paint & Tiles'!$B$28*(1+'Paint & Tiles'!$B$29)*Rates!$C$12 | E11: =B11*(1+'Paint & Tiles'!$B$34)*Rates!$C$13 | F11: =D11+E11 | G11: =IF($F$20=0,"",F11/$F$20)
A12: ='Paint & Tiles'!A12 | B12: ='Paint & Tiles'!H12 | C12: ='Paint & Tiles'!G12 | D12: =C12*'Paint & Tiles'!$B$27/'Paint & Tiles'!$B$28*(1+'Paint & Tiles'!$B$29)*Rates!$C$12 | E12: =B12*(1+'Paint & Tiles'!$B$34)*Rates!$C$13 | F12: =D12+E12 | G12: =IF($F$20=0,"",F12/$F$20)
A13: ='Paint & Tiles'!A13 | B13: ='Paint & Tiles'!H13 | C13: ='Paint & Tiles'!G13 | D13: =C13*'Paint & Tiles'!$B$27/'Paint & Tiles'!$B$28*(1+'Paint & Tiles'!$B$29)*Rates!$C$12 | E13: =B13*(1+'Paint & Tiles'!$B$34)*Rates!$C$13 | F13: =D13+E13 | G13: =IF($F$20=0,"",F13/$F$20)
A14: ='Paint & Tiles'!A14 | B14: ='Paint & Tiles'!H14 | C14: ='Paint & Tiles'!G14 | D14: =C14*'Paint & Tiles'!$B$27/'Paint & Tiles'!$B$28*(1+'Paint & Tiles'!$B$29)*Rates!$C$12 | E14: =B14*(1+'Paint & Tiles'!$B$34)*Rates!$C$13 | F14: =D14+E14 | G14: =IF($F$20=0,"",F14/$F$20)
A15: ='Paint & Tiles'!A15 | B15: ='Paint & Tiles'!H15 | C15: ='Paint & Tiles'!G15 | D15: =C15*'Paint & Tiles'!$B$27/'Paint & Tiles'!$B$28*(1+'Paint & Tiles'!$B$29)*Rates!$C$12 | E15: =B15*(1+'Paint & Tiles'!$B$34)*Rates!$C$13 | F15: =D15+E15 | G15: =IF($F$20=0,"",F15/$F$20)
A16: ='Paint & Tiles'!A16 | B16: ='Paint & Tiles'!H16 | C16: ='Paint & Tiles'!G16 | D16: =C16*'Paint & Tiles'!$B$27/'Paint & Tiles'!$B$28*(1+'Paint & Tiles'!$B$29)*Rates!$C$12 | E16: =B16*(1+'Paint & Tiles'!$B$34)*Rates!$C$13 | F16: =D16+E16 | G16: =IF($F$20=0,"",F16/$F$20)
A17: ='Paint & Tiles'!A17 | B17: ='Paint & Tiles'!H17 | C17: ='Paint & Tiles'!G17 | D17: =C17*'Paint & Tiles'!$B$27/'Paint & Tiles'!$B$28*(1+'Paint & Tiles'!$B$29)*Rates!$C$12 | E17: =B17*(1+'Paint & Tiles'!$B$34)*Rates!$C$13 | F17: =D17+E17 | G17: =IF($F$20=0,"",F17/$F$20)
A20: TOTAL | B20: =SUM(B6:B17) | C20: =SUM(C6:C17) | D20: =SUM(D6:D17) | E20: =SUM(E6:E17) | F20: =SUM(F6:F17)
A22: Room figures are unrounded estimates. Paint & Tiles rounds up to whole litres and tiles, so the totals can differ slightly.

Sheet Stage Budget
A1: STAGE BUDGET
A2: Costs grouped by build stage. Set a target share for each stage and see where you stand.
A3: EXAMPLE RENOVATION: placeholder rates and quantities. These totals are NOT a real estimate.
A5: Stage | B5: Estimated (₹, before contingency & GST) | C5: Share of estimate | D5: Target share (%) | E5: Target (₹) | F5: Actual spent (₹) | G5: Room left (₹) (+ within target) | H5: Status
A6: Site preparation & foundation | B6: =SUMIF('Cost Estimate'!$H$6:$H$25,A6,'Cost Estimate'!$C$6:$C$25) | C6: =IF($B$15=0,0,B6/$B$15) | D6: 0.08 | E6: =D6*Setup!$B$11 | F6: =SUMIF('Cost Estimate'!$H$6:$H$25,A6,'Cost Estimate'!$D$6:$D$25) | G6: =E6-B6 | H6: =IF(E6=0,"Set a target share",IF(B6>E6,"Over target","Within target"))
A7: Structure (concrete & steel) | B7: =SUMIF('Cost Estimate'!$H$6:$H$25,A7,'Cost Estimate'!$C$6:$C$25) | C7: =IF($B$15=0,0,B7/$B$15) | D7: 0.3 | E7: =D7*Setup!$B$11 | F7: =SUMIF('Cost Estimate'!$H$6:$H$25,A7,'Cost Estimate'!$D$6:$D$25) | G7: =E7-B7 | H7: =IF(E7=0,"Set a target share",IF(B7>E7,"Over target","Within target"))
A8: Masonry (walls) | B8: =SUMIF('Cost Estimate'!$H$6:$H$25,A8,'Cost Estimate'!$C$6:$C$25) | C8: =IF($B$15=0,0,B8/$B$15) | D8: 0.15 | E8: =D8*Setup!$B$11 | F8: =SUMIF('Cost Estimate'!$H$6:$H$25,A8,'Cost Estimate'!$D$6:$D$25) | G8: =E8-B8 | H8: =IF(E8=0,"Set a target share",IF(B8>E8,"Over target","Within target"))
A9: Flooring | B9: =SUMIF('Cost Estimate'!$H$6:$H$25,A9,'Cost Estimate'!$C$6:$C$25) | C9: =IF($B$15=0,0,B9/$B$15) | D9: 0.08 | E9: =D9*Setup!$B$11 | F9: =SUMIF('Cost Estimate'!$H$6:$H$25,A9,'Cost Estimate'!$D$6:$D$25) | G9: =E9-B9 | H9: =IF(E9=0,"Set a target share",IF(B9>E9,"Over target","Within target"))
A10: Painting | B10: =SUMIF('Cost Estimate'!$H$6:$H$25,A10,'Cost Estimate'!$C$6:$C$25) | C10: =IF($B$15=0,0,B10/$B$15) | D10: 0.07 | E10: =D10*Setup!$B$11 | F10: =SUMIF('Cost Estimate'!$H$6:$H$25,A10,'Cost Estimate'!$D$6:$D$25) | G10: =E10-B10 | H10: =IF(E10=0,"Set a target share",IF(B10>E10,"Over target","Within target"))
A11: Doors, windows & fittings | B11: =SUMIF('Cost Estimate'!$H$6:$H$25,A11,'Cost Estimate'!$C$6:$C$25) | C11: =IF($B$15=0,0,B11/$B$15) | D11: 0.07 | E11: =D11*Setup!$B$11 | F11: =SUMIF('Cost Estimate'!$H$6:$H$25,A11,'Cost Estimate'!$D$6:$D$25) | G11: =E11-B11 | H11: =IF(E11=0,"Set a target share",IF(B11>E11,"Over target","Within target"))
A12: Plumbing & electrical | B12: =SUMIF('Cost Estimate'!$H$6:$H$25,A12,'Cost Estimate'!$C$6:$C$25) | C12: =IF($B$15=0,0,B12/$B$15) | D12: 0.12 | E12: =D12*Setup!$B$11 | F12: =SUMIF('Cost Estimate'!$H$6:$H$25,A12,'Cost Estimate'!$D$6:$D$25) | G12: =E12-B12 | H12: =IF(E12=0,"Set a target share",IF(B12>E12,"Over target","Within target"))
A13: Kitchen & bathrooms | B13: =SUMIF('Cost Estimate'!$H$6:$H$25,A13,'Cost Estimate'!$C$6:$C$25) | C13: =IF($B$15=0,0,B13/$B$15) | D13: 0.08 | E13: =D13*Setup!$B$11 | F13: =SUMIF('Cost Estimate'!$H$6:$H$25,A13,'Cost Estimate'!$D$6:$D$25) | G13: =E13-B13 | H13: =IF(E13=0,"Set a target share",IF(B13>E13,"Over target","Within target"))
A14: Approvals, fees & other | B14: =SUMIF('Cost Estimate'!$H$6:$H$25,A14,'Cost Estimate'!$C$6:$C$25) | C14: =IF($B$15=0,0,B14/$B$15) | D14: 0.05 | E14: =D14*Setup!$B$11 | F14: =SUMIF('Cost Estimate'!$H$6:$H$25,A14,'Cost Estimate'!$D$6:$D$25) | G14: =E14-B14 | H14: =IF(E14=0,"Set a target share",IF(B14>E14,"Over target","Within target"))
A15: TOTAL | B15: =SUM(B6:B14) | C15: =SUM(C6:C14) | D15: =SUM(D6:D14) | E15: =SUM(E6:E14) | F15: =SUM(F6:F14) | G15: =E15-B15
A17: =IF(ROUND(B15-'Cost Estimate'!C26,0)=0,"Check: every cost is assigned to a stage.","Warning: some costs have no stage. Check the Stage column on Cost Estimate.")
A18: Target shares should add up to 100%. The shares shown are examples only. Set your own to match your plan.
A19: =IF(ROUND(D15,4)=1,"Target shares add up to 100%.","Warning: target shares add up to "&TEXT(D15,"0%")&". Adjust them to 100%.")

Sheet Stage Checklist
A1: STAGE CHECKLIST
A2: Checks to do before moving to the next stage. These are general points. Your engineer or site supervisor decides the actual requirements.
A3: EXAMPLE RENOVATION: placeholder rates and quantities. These totals are NOT a real estimate.
A5: Stage | B5: Check before moving on | C5: Done? | D5: Date checked | E5: Who checked | F5: Notes
A6: Site preparation & foundation
A7: Site preparation & foundation | B7: Soil test report received
A8: Site preparation & foundation | B8: Layout marked and checked against the approved plan
A9: Site preparation & foundation | B9: Foundation depth and width inspected before concrete is poured
A10: Structure (concrete & steel)
A11: Structure (concrete & steel) | B11: Steel bar size, spacing and cover match the drawings before concrete
A12: Structure (concrete & steel) | B12: Concrete grade as specified; test cubes taken
A13: Structure (concrete & steel) | B13: Formwork checked for level and alignment
A14: Structure (concrete & steel) | B14: Curing started and recorded
A15: Masonry (walls)
A16: Masonry (walls) | B16: Walls checked for alignment and vertical level
A17: Masonry (walls) | B17: Mortar mix as specified
A18: Masonry (walls) | B18: Lintels or bands in place above openings
A19: Flooring
A20: Flooring | B20: Floor surface level and dry
A21: Flooring | B21: Tile layout planned before fixing
A22: Flooring | B22: Tiles from the same batch
A23: Flooring | B23: Joints checked after fixing
A24: Painting
A25: Painting | B25: Walls fully dry and plastered
A26: Painting | B26: Primer applied
A27: Painting | B27: Number of coats as specified
A28: Painting | B28: Paint batch numbers recorded
A29: Doors, windows & fittings
A30: Doors, windows & fittings | B30: Frames fixed plumb and level
A31: Doors, windows & fittings | B31: Hardware and glass match the order
A32: Doors, windows & fittings | B32: Gaps around frames sealed
A33: Plumbing & electrical
A34: Plumbing & electrical | B34: Water lines pressure-tested
A35: Plumbing & electrical | B35: Electrical circuits and earthing tested
A36: Plumbing & electrical | B36: Concealed work photographed before walls are closed
A37: Kitchen & bathrooms
A38: Kitchen & bathrooms | B38: Waterproofing tested (ponding test) before tiling
A39: Kitchen & bathrooms | B39: Fittings match the order
A40: Kitchen & bathrooms | B40: Drainage tested to flow freely
A41: Approvals, fees & other
...

Sheet Order List
A1: ORDER LIST
A2: What to buy, how much, from whom, and by when. Quantities come from the calculators.
A3: EXAMPLE RENOVATION: placeholder rates and quantities. These totals are NOT a real estimate.
A5: Material | B5: Stage | C5: Unit | D5: Calculated quantity | E5: Extra for wastage (%) | F5: Order quantity | G5: Unit rate (₹) | H5: Line cost (₹) | I5: Supplier | J5: Order by | K5: Ordered? | L5: Received?
A6: Cement (50 kg bag) | B6: Structure (concrete & steel) | C6: bags | D6: =Concrete!B25 | E6: 0 | F6: =ROUNDUP(D6*(1+E6),0) | G6: =Rates!$C$6 | H6: =F6*G6
A7: M-sand | B7: Structure (concrete & steel) | C7: cu ft | D7: =Concrete!B26 | E7: 0.1 | F7: =ROUNDUP(D7*(1+E7),0) | G7: =Rates!$C$7 | H7: =F7*G7
A8: 20 mm aggregate | B8: Structure (concrete & steel) | C8: cu ft | D8: =Concrete!B27 | E8: 0.05 | F8: =ROUNDUP(D8*(1+E8),0) | G8: =Rates!$C$8 | H8: =F8*G8
A9: TMT steel 8 mm | B9: Structure (concrete & steel) | C9: kg | D9: =Steel!D6 | E9: 0.05 | F9: =ROUNDUP(D9*(1+E9),0) | G9: =Rates!$C$11 | H9: =F9*G9
A10: TMT steel 10 mm | B10: Structure (concrete & steel) | C10: kg | D10: =Steel!D7 | E10: 0.05 | F10: =ROUNDUP(D10*(1+E10),0) | G10: =Rates!$C$11 | H10: =F10*G10
A11: TMT steel 12 mm | B11: Structure (concrete & steel) | C11: kg | D11: =Steel!D8 | E11: 0.05 | F11: =ROUNDUP(D11*(1+E11),0) | G11: =Rates!$C$11 | H11: =F11*G11
A12: TMT steel 16 mm | B12: Structure (concrete & steel) | C12: kg | D12: =Steel!D9 | E12: 0.05 | F12: =ROUNDUP(D12*(1+E12),0) | G12: =Rates!$C$11 | H12: =F12*G12
A13: TMT steel 20 mm | B13: Structure (concrete & steel) | C13: kg | D13: =Steel!D10 | E13: 0.05 | F13: =ROUNDUP(D13*(1+E13),0) | G13: =Rates!$C$11 | H13: =F13*G13
A14: Red clay bricks | B14: Masonry (walls) | C14: pieces | D14: ='Bricks & Blocks'!B21 | E14: 0 | F14: =ROUNDUP(D14*(1+E14),0) | G14: =Rates!$C$9 | H14: =F14*G14
A15: Floor tiles | B15: Flooring | C15: tiles | D15: ='Paint & Tiles'!B41 | E15: 0 | F15: =ROUNDUP(D15*(1+E15),0) | G15: =Rates!$C$13*('Paint & Tiles'!$B$32/304.8)*('Paint & Tiles'!$B$33/304.8) | H15: =F15*G15
A16: Interior paint | B16: Painting | C16: litres | D16: ='Paint & Tiles'!B38 | E16: 0 | F16: =ROUNDUP(D16*(1+E16),0) | G16: =Rates!$C$12 | H16: =F16*G16
A17: Cement (plaster) | B17: Masonry (walls) | C17: bags | D17: =Plaster!B19 | E17: 0 | F17: =ROUNDUP(D17*(1+E17),0) | G17: =Rates!$C$6 | H17: =F17*G17
A18: M-sand (plaster) | B18: Masonry (walls) | C18: cu ft | D18: =Plaster!B20 | E18: 0 | F18: =ROUNDUP(D18*(1+E18),0) | G18: =Rates!$C$7 | H18: =F18*G18
F19: =IF(D19="","",ROUNDUP(D19*(1+IF(E19="",0,E19)),0)) | H19: =IF(OR(F19="",G19=""),"",F19*G19)
F20: =IF(D20="","",ROUNDUP(D20*(1+IF(E20="",0,E20)),0)) | H20: =IF(OR(F20="",G20=""),"",F20*G20)
F21: =IF(D21="","",ROUNDUP(D21*(1+IF(E21="",0,E21)),0)) | H21: =IF(OR(F21="",G21=""),"",F21*G21)
F22: =IF(D22="","",ROUNDUP(D22*(1+IF(E22="",0,E22)),0)) | H22: =IF(OR(F22="",G22=""),"",F22*G22)
F23: =IF(D23="","",ROUNDUP(D23*(1+IF(E23="",0,E23)),0)) | H23: =IF(OR(F23="",G23=""),"",F23*G23)
F24: =IF(D24="","",ROUNDUP(D24*(1+IF(E24="",0,E24)),0)) | H24: =IF(OR(F24="",G24=""),"",F24*G24)
A25: TOTAL MATERIAL COST | H25: =SUM(H6:H24)
A27: Wastage starts at the defaults shown. Change them to match your supplier's advice.
A28: Bricks and tiles already include their breakage allowance, so no extra wastage is added here.
A29: Use the spare rows for paint primer, sanitary items or anything else you buy. Enter the quantity and rate by hand.
A30: This list covers materials only. Labour, transport and fittings are on the Cost Estimate tab.

Sheet Task Tracker
A1: TASK TRACKER
A2: Every job on the build, who does it, and when it is due. Overdue tasks turn red.
A3: EXAMPLE RENOVATION: placeholder rates and quantities. These totals are NOT a real estimate.
A5: Task | B5: Stage | C5: Room / area | D5: Assigned to | E5: Start date | F5: Due date | G5: Priority | H5: Status | I5: Days left | K5: STATUS SUMMARY
A6: Get building approval | C6: General | D6: Owner | G6: High | H6: Not started | I6: =IF(F6="","",F6-TODAY()) | K6: Not started | L6: =COUNTIF($H$6:$H$45,K6)
A7: Soil test | C7: General | D7: Soil tester | G7: High | H7: Not started | I7: =IF(F7="","",F7-TODAY()) | K7: In progress | L7: =COUNTIF($H$6:$H$45,K7)
A8: Mark layout on site | C8: General | D8: Engineer / mason | G8: High | H8: Not started | I8: =IF(F8="","",F8-TODAY()) | K8: Done | L8: =COUNTIF($H$6:$H$45,K8)
A9: Order cement and steel | C9: General | D9: Owner | G9: High | H9: Not started | I9: =IF(F9="","",F9-TODAY()) | K9: On hold | L9: =COUNTIF($H$6:$H$45,K9)
A10: Steel bar check before concrete | C10: General | D10: Engineer | G10: High | H10: Not started | I10: =IF(F10="","",F10-TODAY()) | K10: Overdue (not Done) | L10: =COUNTIFS($I$6:$I$45,"<0",$H$6:$H$45,"<>Done")
A11: Brickwork to lintel level | C11: General | D11: Mason | G11: Medium | H11: Not started | I11: =IF(F11="","",F11-TODAY())
A12: Plumbing lines in walls | C12: Bathrooms | D12: Plumber | G12: Medium | H12: Not started | I12: =IF(F12="","",F12-TODAY())
A13: Electrical conduits in walls | C13: General | D13: Electrician | G13: Medium | H13: Not started | I13: =IF(F13="","",F13-TODAY())
A14: Waterproofing test | C14: Bathrooms | D14: Waterproofing contractor | G14: High | H14: Not started | I14: =IF(F14="","",F14-TODAY())
A15: Order floor tiles | C15: General | D15: Owner | G15: Medium | H15: Not started | I15: =IF(F15="","",F15-TODAY())
A16: Paint primer coat | C16: General | D16: Painter | G16: Low | H16: Not started | I16: =IF(F16="","",F16-TODAY())
A17: Final inspection | C17: General | D17: Engineer | G17: High | H17: Not started | I17: =IF(F17="","",F17-TODAY())
I18: =IF(F18="","",F18-TODAY())
I19: =IF(F19="","",F19-TODAY())
I20: =IF(F20="","",F20-TODAY())
I21: =IF(F21="","",F21-TODAY())
I22: =IF(F22="","",F22-TODAY())
I23: =IF(F23="","",F23-TODAY())
I24: =IF(F24="","",F24-TODAY())
I25: =IF(F25="","",F25-TODAY())
I26: =IF(F26="","",F26-TODAY())
I27: =IF(F27="","",F27-TODAY())
I28: =IF(F28="","",F28-TODAY())
I29: =IF(F29="","",F29-TODAY())
... I45: =IF(F45="","",F45-TODAY())
A47: Overdue = due date has passed and the task is not Done. Days left is counted from today.
A48: Pre-filled tasks are examples. Change or delete them to suit your build.

Sheet Permits
A1: PERMITS & APPROVALS
A2: Track each approval your build needs. Which ones apply depends on your city and project. Check with your local authority.
A3: EXAMPLE RENOVATION: placeholder rates and quantities. These totals are NOT a real estimate.
A5: Approval / permit | B5: Who issues it | C5: Needed for your project? | D5: Applied on | E5: Approved on | F5: Status | G5: Reference number | H5: Notes | I5: Fee (₹)
A6: Building plan approval | B6: Local development / planning authority | C6: Check | F6: Not applied
A7: Building permit or commencement certificate | B7: Local development / planning authority | C7: Check | F7: Not applied
A8: Structural engineer's certificate | B8: Licensed structural engineer | C8: Check | F8: Not applied
A9: Soil test report | B9: Accredited soil testing lab | C9: Check | F9: Not applied
A10: Water connection | B10: Local water supply authority | C10: Check | F10: Not applied
A11: Sewer connection | B11: Local sewerage authority | C11: Check | F11: Not applied
A12: Temporary electricity connection | B12: Electricity distribution company | C12: Check | F12: Not applied
A13: Permanent electricity connection | B13: Electricity distribution company | C13: Check | F13: Not applied
A14: Occupancy / completion certificate | B14: Local development / planning authority | C14: Check | F14: Not applied
A15: Property tax registration | B15: Local municipal body | C15: Check | F15: Not applied
A26: TOTAL FEES AND APPROVAL COSTS | I26: =SUM(I6:I25)
A27: Check with your engineer and local authority which approvals must come before work starts. Local rules decide the order.
A28: These are the usual approvals, not a legal list. Your local authority decides what applies to your plot.

Sheet Rates
A1: RATES
A2: Type in your local rates. Blank rates show zero cost until you enter them.
A3: EXAMPLE RENOVATION: placeholder rates and quantities. These totals are NOT a real estimate.
A4: Item | B4: Unit | C4: Your rate (₹) | D4: Supplier / source | E4: Date updated
A6: Cement | B6: per 50 kg bag | C6: 600 | D6: Sample figure, not a quote
A7: M-sand | B7: per cu ft | C7: 60 | D7: Sample figure, not a quote
A8: 20 mm aggregate | B8: per cu ft | C8: 70 | D8: Sample figure, not a quote
A9: Red clay brick | B9: per piece | C9: 9 | D9: Sample figure, not a quote
A10: AAC block | B10: per piece | C10: 80 | D10: Sample figure, not a quote
A11: TMT steel | B11: per kg | C11: 75 | D11: Sample figure, not a quote
A12: Interior paint | B12: per litre | C12: 350 | D12: Sample figure, not a quote
A13: Floor tile | B13: per sq ft | C13: 40 | D13: Sample figure, not a quote
A14: Concrete labour | B14: per cu ft | C14: 50 | D14: Sample figure, not a quote
A15: Masonry labour | B15: per sq ft | C15: 120 | D15: Sample figure, not a quote
A16: Excavation | B16: per cu ft | C16: 35 | D16: Sample figure, not a quote
A17: Exterior paint | B17: per litre | C17: 350 | D17: Sample figure, not a quote
... A21: Tile laying labour | B21: per sq ft of floor | C21: 10 | D21: Sample figure, not a quote
A23: Tip: get quotes from at least two suppliers. The Rate Library can store them.
A24: EXAMPLE FILE: every rate above is a placeholder to show how the file works. Replace all of them with your own quotes.

Sheet Rate Quotes
A1: RATE QUOTES
A2: Compare two supplier quotes for each item. Only compare quotes that cover the same delivery and loading terms.
A3: EXAMPLE RENOVATION: placeholder rates and quantities. These totals are NOT a real estimate.
A5: Item | B5: Unit (as on Rates tab) | C5: Supplier A | D5: Rate A (₹) | E5: A includes delivery and loading? (Yes/No) | F5: Supplier B | G5: Rate B (₹) | H5: B includes delivery and loading? (Yes/No) | I5: Lower rate, same terms (₹)
A6: Cement | B6: per 50 kg bag | I6: =IF(COUNT(D6,G6)<2,"",IF(E6=H6,MIN(D6,G6),"Terms differ: ask both for the same terms"))
A7: M-sand | B7: per cu ft | I7: =IF(COUNT(D7,G7)<2,"",IF(E7=H7,MIN(D7,G7),"Terms differ: ask both for the same terms"))
A8: 20 mm aggregate | B8: per cu ft | I8: =IF(COUNT(D8,G8)<2,"",IF(E8=H8,MIN(D8,G8),"Terms differ: ask both for the same terms"))
A9: Red clay brick | B9: per piece | I9: =IF(COUNT(D9,G9)<2,"",IF(E9=H9,MIN(D9,G9),"Terms differ: ask both for the same terms"))
A10: AAC block | B10: per piece | I10: =IF(COUNT(D10,G10)<2,"",IF(E10=H10,MIN(D10,G10),"Terms differ: ask both for the same terms"))
A11: TMT steel | B11: per kg | I11: =IF(COUNT(D11,G11)<2,"",IF(E11=H11,MIN(D11,G11),"Terms differ: ask both for the same terms"))
A12: Interior paint | B12: per litre | I12: =IF(COUNT(D12,G12)<2,"",IF(E12=H12,MIN(D12,G12),"Terms differ: ask both for the same terms"))
A13: Floor tile | B13: per sq ft | I13: =IF(COUNT(D13,G13)<2,"",IF(E13=H13,MIN(D13,G13),"Terms differ: ask both for the same terms"))
A14: Concrete labour | B14: per cu ft | I14: =IF(COUNT(D14,G14)<2,"",IF(E14=H14,MIN(D14,G14),"Terms differ: ask both for the same terms"))
A15: Masonry labour | B15: per sq ft | I15: =IF(COUNT(D15,G15)<2,"",IF(E15=H15,MIN(D15,G15),"Terms differ: ask both for the same terms"))
A16: Excavation | B16: per cu ft | I16: =IF(COUNT(D16,G16)<2,"",IF(E16=H16,MIN(D16,G16),"Terms differ: ask both for the same terms"))
A17: Exterior paint | B17: per litre | I17: =IF(COUNT(D17,G17)<2,"",IF(E17=H17,MIN(D17,G17),"Terms differ: ask both for the same terms"))
... A21: Tile laying labour | B21: per sq ft of floor | I21: =IF(COUNT(D21,G21)<2,"",IF(E21=H21,MIN(D21,G21),"Terms differ: ask both for the same terms"))
A23: Copy the lower rate from column I to the Rates tab, and record the supplier and date there.

Sheet Assumptions
A1: ASSUMPTIONS
A2: Every factor the calculations use. Change the value on the tab shown. Source status must be confirmed before you rely on a figure.
A3: EXAMPLE RENOVATION: placeholder rates and quantities. These totals are NOT a real estimate.
A4: Factor | B4: Current value | C4: Unit | D4: Where to change it | E4: Source status | F4: Verified value (engineer fills) | G4: Verified by | H4: Source reference | I4: Date verified
A5: Contingency | B5: =Setup!B12 | C5: % | D5: Setup | E5: Your choice. Set by you.
A6: GST on works | B6: =Setup!B13 | C6: % | D6: Setup | E6: NOT VERIFIED. Confirm the rate for your contract with your accountant.
A7: Dry volume factor (wet to dry concrete) | B7: =Concrete!B20 | C7: x | D7: Concrete | E7: Common practice. Not sourced. Engineer to confirm.
A8: Cement parts (mix) | B8: =Concrete!B17 | C8: parts | D8: Concrete | E8: Example mix only. Use your engineer's grade and mix.
A9: Sand parts (mix) | B9: =Concrete!B18 | C9: parts | D9: Concrete | E9: Example mix only. Use your engineer's grade and mix.
A10: Aggregate parts (mix) | B10: =Concrete!B19 | C10: parts | D10: Concrete | E10: Example mix only. Use your engineer's grade and mix.
A11: Cement bag volume (1.25 cu ft per 50 kg bag) | B11: 1.25 | C11: cu ft | D11: This tab (row 11) | E11: Practice. Not sourced. Supplier to confirm.
A12: Bricks per cu m of wall | B12: ='Bricks & Blocks'!B14 | C12: pieces | D12: Bricks & Blocks | E12: Approximation. Not sourced. Mason to confirm.
A13: Brick breakage allowance | B13: ='Bricks & Blocks'!B15 | C13: % | D13: Bricks & Blocks | E13: Practice. Not sourced.
A14: Paint coverage | B14: ='Paint & Tiles'!B28 | C14: sq ft per litre | D14: Paint & Tiles | E14: Assumption. Check the coverage on the paint label.
A15: Paint waste allowance | B15: ='Paint & Tiles'!B29 | C15: % | D15: Paint & Tiles | E15: Practice. Not sourced.
A16: Number of coats | B16: ='Paint & Tiles'!B27 | C16: coats | D16: Paint & Tiles | E16: Your choice. Check with the painter.
A17: Standard door size (width) | B17: ='Paint & Tiles'!B21 | C17: units | D17: Paint & Tiles | E17: Assumption. Measure your doors.
A18: Standard window size (width) | B18: ='Paint & Tiles'!B23 | C18: units | D18: Paint & Tiles | E18: Assumption. Measure your windows.
A19: Tile size (length) | B19: ='Paint & Tiles'!B32 | C19: mm | D19: Paint & Tiles | E19: Assumption. Use your tile's size.
A20: Tile cutting and breakage allowance | B20: ='Paint & Tiles'!B34 | C20: % | D20: Paint & Tiles | E20: Practice. Not sourced.
A21: Steel weight constant (diameter² ÷ 162) | B21: 162 | C21: kg per m | D21: This tab (row 21) | E21: Unit-weight formula for TMT bars. Engineer to confirm against IS 1786.
A22: Plaster thickness | B22: =Plaster!B10 | C22: mm | D22: Plaster | E22: Practice. Not sourced.
A23: Plaster mix (cement : sand) | B23: =Plaster!B12&" : "&Plaster!B13 | C23: parts | D23: Plaster | E23: Practice. Not sourced.
A24: Plaster dry volume factor | B24: =Plaster!B11 | C24: x | D24: Plaster | E24: Practice. Not sourced.
A25: Plaster waste allowance | B25: =Plaster!B14 | C25: % | D25: Plaster | E25: Practice. Not sourced.
A26: Excavation over-digging allowance | B26: =Earthwork!B17 | C26: % | D26: Earthwork | E26: Practice. Not sourced.
A27: Wastage on sand (Order List) | B27: ='Order List'!E7 | C27: % | D27: Order List | E27: Practice. Not sourced. Supplier to confirm.
A28: Wastage on aggregate and steel (Order List) | B28: ='Order List'!E8 | C28: % | D28: Order List | E28: Practice. Not sourced. Supplier to confirm.
A29: Bill check tolerance | B29: ='Bill Check'!B4 | C29: % | D29: Bill Check | E29: Your choice.
A30: Quotation valid for | B30: ='Quotation'!C36 | C30: days | D30: Quotation | E30: Your choice. Check local practice.
A31: Stage target shares | B31: Stage Budget column D | C31: % | D31: Stage Budget | E31: Examples only. Set your own.
A32: Conversion factors (ft to m, sq ft to sq m, cu ft to cu m, mm to ft) | B32: 3.28084 / 10.7639 / 35.3147 / 304.8 | C32: - | D32: Fixed in formula | E32: Exact unit conversions.
A34: Nothing on this tab is a source. Each line says whether it has been checked. Until it is, treat the figure as an estimate.
A35: Engineer or quantity surveyor: fill columns F to I for each factor you confirm. Leave blank any factor you cannot confirm.

Sheet Terms & Disclaimer
A1: TERMS & DISCLAIMER
A2: Read before relying on any figure in this file.
A3: EXAMPLE RENOVATION: placeholder rates and quantities. These totals are NOT a real estimate.
A4: What this file is | B4: A planning tool. It calculates quantities and costs from the measurements, rates and assumptions you enter.
A5: What this file is not | B5: It is not a structural design. It does not check loads, safety or building bylaws. It does not replace a structural engineer, architect, quantity surveyor or licensed contractor.
A6: Estimates only | B6: Results depend on your measurements, your rates and the assumptions on the Assumptions tab. Rates are blank or placeholders until you enter your own.
A7: Sample figures | B7: The EXAMPLE file's rates and quantities are placeholders. Do not use them as market prices or as a benchmark for cost per sq ft.
A8: Not professional advice | B8: This is not legal, tax, financial or building advice. Confirm GST, approvals and contract terms with your accountant, lawyer and local authority.
A9: Compatibility & Testing | B9: Formulas use standard OpenXML spreadsheet functions verified for Microsoft Excel (2016-365, Windows & Mac), Google Sheets, and LibreOffice Calc. Check all project-specific figures before placing orders or signing contracts.
A10: Your responsibility | B10: You decide what to buy, pay for, and build. Check every quantity and rate before you act on it.
A11: Support & License | B11: Published by Thinktools (thinktools.in). Customer Support: orders@thinktools.in. Licensed for single-user personal and business planning. All sales final; replacement support available.

Sheet Dashboard
A1: DASHBOARD
A2: Your project at a glance. Everything here updates as you change the other tabs.
A3: EXAMPLE RENOVATION: placeholder rates and quantities. These totals are NOT a real estimate.
A4: PROJECT
A5: Project | B5: =Setup!B5
A6: Location | B6: =Setup!B7
A7: Built-up area | B7: =TEXT(Setup!B10,"#,##0")&" "&IF(Setup!$B$9="Metres","sq m","sq ft")
A8: Target budget (₹) | B8: =Setup!B11
A10: MONEY
A11: Estimated total (₹) | B11: ='Cost Estimate'!C29
A12: Actual spent (₹) | B12: ='Cost Estimate'!D29
A13: Headroom vs target (₹) | B13: ='Cost Estimate'!C31
A14: Cost per sq ft (₹) | B14: ='Cost Estimate'!C32
A15: Spent so far (% of estimate) | B15: =IF(B11=0,0,B12/B11)
A17: MATERIALS
A18: Paint to buy (litres) | B18: ='Paint & Tiles'!B38
A19: Floor tiles to buy | B19: ='Paint & Tiles'!B41
A20: Bricks needed | B20: ='Bricks & Blocks'!B21
A21: Cement bags (50 kg) | B21: =Concrete!B25
A22: Steel (tonnes) | B22: =Steel!E12
A23: Concrete (cu ft) | B23: =Concrete!F14
A24: Material cost from Order List (₹) | B24: ='Order List'!H25
A26: ='Cost Estimate'!A34
A28: Actual-spend bars stay empty until you enter actual spend on the Cost Estimate tab.
A32: =IF(COUNTBLANK(Rates!C6:C21)>0,"Next step: enter your rates on the Rates tab. Costs show zero until you do. Use Rate Quotes to compare two suppliers.",IF(COUNT(Services!B6:B22)=0,"Next step: count plumbing and electrical points on the Services tab.","Next step: check the Stage Budget and set your own target shares."))

Sheet Bill Check
A1: BILL CHECK
A2: Compare the quantities a contractor claims with the quantities this file calculates.
A3: EXAMPLE RENOVATION: placeholder rates and quantities. These totals are NOT a real estimate.
A4: Allowed difference before flagging (%) | B4: 0.05
A6: Item | B6: Unit | C6: Our calculation | D6: Contractor's claim | E6: Difference | F6: Difference % | G6: Result
A7: Room area | B7: sq ft | C7: ='Room Area'!E18 | E7: =IF(D7="","",D7-C7) | F7: =IF(OR(D7="",C7=0),"",E7/C7) | G7: =IF(D7="","Enter the claim",IF(F7>$B$4,"Claim is higher. Ask for the measurement sheet.",IF(F7<-$B$4,"Claim is lower. Check the scope is complete.","Within the allowed difference")))
A8: Concrete volume | B8: cu ft | C8: =Concrete!F14 | E8: =IF(D8="","",D8-C8) | F8: =IF(OR(D8="",C8=0),"",E8/C8) | G8: =IF(D8="","Enter the claim",IF(F8>$B$4,"Claim is higher. Ask for the measurement sheet.",IF(F8<-$B$4,"Claim is lower. Check the scope is complete.","Within the allowed difference")))
